Workbook

Sheet Ventes cumulatives par magasin
A1: please only use columns in light blue | F1: HT-Piscine hors-terre | G1: HT-Piscine hors-terre | H1: CR-Piscine creusée | I1: CR-Piscine creusée | J1: SP-Spa | K1: SP-Spa | L1: ME-Meuble | M1: GA-Gazebo et Abri | N1: ME-Meuble & GA-Gazebo | O1: FI-Fitness | P1: BQ-BBQ
A2: Commence le | B2: Semaine fiscale | C2: Month | D2: Année fiscale | E2: Code magasin | F2: U-HT | G2: $-HT | H2: U-CR | I2: $-CR | J2: U-SP | K2: $-SP | L2: $-ME | M2: $-GA | N2: $-ME & $-GA | O2: $-FI | P2: $-BQ
A3: 44865 | B3: 1 | C3: =MONTH(A3) -> 10 | D3: 2023 | E3: CP01 | F3: 0 | G3: =IF($D3=2023,F3*'Average selling price'!$B$2, IF($D3=2024,F3*'Average selling price'!$C$2, IF($D3=2025,F3*'Average selling price'!$D$2,""))) -> 0 | H3: 0 | I3: =IF($D3=2023,H3*'Average selling price'!$B$3, IF($D3=2024,H3*'Average selling price'!$C$3, IF($D3=2025,H3*'Average selling price'!$D$3,""))) -> 0 | J3: 2 | K3: =IF($D3=2023,J3*'Average selling price'!$B$4, IF($D3=2024,J3*'Average selling price'!$C$4, IF($D3=2025,J3*'Average selling price'!$D$4,""))) -> 21536 | L3: 8779 | M3: 2210 | N3: =M3+L3 -> 10989 | O3: 18165 | P3: 2015
A4: 44865 | B4: 1 | C4: =MONTH(A4) -> 10 | D4: 2023 | E4: CP02 | F4: 1 | G4: =IF(D4=2023,F4*'Average selling price'!$B$2, IF(D4=2024,F4*'Average selling price'!$C$2, IF(D4=2025,F4*'Average selling price'!$D$2,""))) -> 4919 | H4: 0 | I4: =IF($D4=2023,H4*'Average selling price'!$B$3, IF($D4=2024,H4*'Average selling price'!$C$3, IF($D4=2025,H4*'Average selling price'!$D$3,""))) -> 0 | J4: 1 | K4: =IF($D4=2023,J4*'Average selling price'!$B$4, IF($D4=2024,J4*'Average selling price'!$C$4, IF($D4=2025,J4*'Average selling price'!$D$4,""))) -> 10768 | L4: 1671 | M4: 0 | N4: =M4+L4 -> 1671 | O4: 0 | P4: 65
A5: 44865 | B5: 1 | C5: =MONTH(A5) -> 10 | D5: 2023 | E5: CP03 | F5: 0 | G5: =IF(D5=2023,F5*'Average selling price'!$B$2, IF(D5=2024,F5*'Average selling price'!$C$2, IF(D5=2025,F5*'Average selling price'!$D$2,""))) -> 0 | H5: 0 | I5: =IF($D5=2023,H5*'Average selling price'!$B$3, IF($D5=2024,H5*'Average selling price'!$C$3, IF($D5=2025,H5*'Average selling price'!$D$3,""))) -> 0 | J5: 2 | K5: =IF($D5=2023,J5*'Average selling price'!$B$4, IF($D5=2024,J5*'Average selling price'!$C$4, IF($D5=2025,J5*'Average selling price'!$D$4,""))) -> 21536 | L5: 700 | M5: 0 | N5: =M5+L5 -> 700 | O5: 1049 | P5: 0
A6: 44865 | B6: 1 | C6: =MONTH(A6) -> 10 | D6: 2023 | E6: CP04 | F6: 2 | G6: =IF(D6=2023,F6*'Average selling price'!$B$2, IF(D6=2024,F6*'Average selling price'!$C$2, IF(D6=2025,F6*'Average selling price'!$D$2,""))) -> 9838 | H6: 0 | I6: =IF($D6=2023,H6*'Average selling price'!$B$3, IF($D6=2024,H6*'Average selling price'!$C$3, IF($D6=2025,H6*'Average selling price'!$D$3,""))) -> 0 | J6: 1 | K6: =IF($D6=2023,J6*'Average selling price'!$B$4, IF($D6=2024,J6*'Average selling price'!$C$4, IF($D6=2025,J6*'Average selling price'!$D$4,""))) -> 10768 | L6: 559 | M6: 1942 | N6: =M6+L6 -> 2501 | O6: 426 | P6: 0
A7: 44865 | B7: 1 | C7: =MONTH(A7) -> 10 | D7: 2023 | E7: CP05 | F7: 3 | G7: =IF(D7=2023,F7*'Average selling price'!$B$2, IF(D7=2024,F7*'Average selling price'!$C$2, IF(D7=2025,F7*'Average selling price'!$D$2,""))) -> 14757 | H7: 1 | I7: =IF($D7=2023,H7*'Average selling price'!$B$3, IF($D7=2024,H7*'Average selling price'!$C$3, IF($D7=2025,H7*'Average selling price'!$D$3,""))) -> 29064 | J7: 5 | K7: =IF($D7=2023,J7*'Average selling price'!$B$4, IF($D7=2024,J7*'Average selling price'!$C$4, IF($D7=2025,J7*'Average selling price'!$D$4,""))) -> 53840 | L7: 2014 | M7: 1490 | N7: =M7+L7 -> 3504 | O7: 1371 | P7: 1204
A8: 44865 | B8: 1 | C8: =MONTH(A8) -> 10 | D8: 2023 | E8: CP06 | F8: 1 | G8: =IF(D8=2023,F8*'Average selling price'!$B$2, IF(D8=2024,F8*'Average selling price'!$C$2, IF(D8=2025,F8*'Average selling price'!$D$2,""))) -> 4919 | H8: 0 | I8: =IF($D8=2023,H8*'Average selling price'!$B$3, IF($D8=2024,H8*'Average selling price'!$C$3, IF($D8=2025,H8*'Average selling price'!$D$3,""))) -> 0 | J8: 1 | K8: =IF($D8=2023,J8*'Average selling price'!$B$4, IF($D8=2024,J8*'Average selling price'!$C$4, IF($D8=2025,J8*'Average selling price'!$D$4,""))) -> 10768 | L8: 6919 | M8: 4775 | N8: =M8+L8 -> 11694 | O8: 34 | P8: 16
A9: 44865 | B9: 1 | C9: =MONTH(A9) -> 10 | D9: 2023 | E9: CP07 | F9: 3 | G9: =IF(D9=2023,F9*'Average selling price'!$B$2, IF(D9=2024,F9*'Average selling price'!$C$2, IF(D9=2025,F9*'Average selling price'!$D$2,""))) -> 14757 | H9: 0 | I9: =IF($D9=2023,H9*'Average selling price'!$B$3, IF($D9=2024,H9*'Average selling price'!$C$3, IF($D9=2025,H9*'Average selling price'!$D$3,""))) -> 0 | J9: 4 | K9: =IF($D9=2023,J9*'Average selling price'!$B$4, IF($D9=2024,J9*'Average selling price'!$C$4, IF($D9=2025,J9*'Average selling price'!$D$4,""))) -> 43072 | L9: 22941 | M9: 21519 | N9: =M9+L9 -> 44460 | O9: 7799 | P9: 0
A10: 44865 | B10: 1 | C10: =MONTH(A10) -> 10 | D10: 2023 | E10: CP08 | F10: 4 | G10: =IF(D10=2023,F10*'Average selling price'!$B$2, IF(D10=2024,F10*'Average selling price'!$C$2, IF(D10=2025,F10*'Average selling price'!$D$2,""))) -> 19676 | H10: 0 | I10: =IF($D10=2023,H10*'Average selling price'!$B$3, IF($D10=2024,H10*'Average selling price'!$C$3, IF($D10=2025,H10*'Average selling price'!$D$3,""))) -> 0 | J10: 4 | K10: =IF($D10=2023,J10*'Average selling price'!$B$4, IF($D10=2024,J10*'Average selling price'!$C$4, IF($D10=2025,J10*'Average selling price'!$D$4,""))) -> 43072 | L10: 7738 | M10: 300 | N10: =M10+L10 -> 8038 | O10: 5050 | P10: 0
A11: 44865 | B11: 1 | C11: =MONTH(A11) -> 10 | D11: 2023 | E11: CP10 | F11: 1 | G11: =IF(D11=2023,F11*'Average selling price'!$B$2, IF(D11=2024,F11*'Average selling price'!$C$2, IF(D11=2025,F11*'Average selling price'!$D$2,""))) -> 4919 | H11: 0 | I11: =IF($D11=2023,H11*'Average selling price'!$B$3, IF($D11=2024,H11*'Average selling price'!$C$3, IF($D11=2025,H11*'Average selling price'!$D$3,""))) -> 0 | J11: 5 | K11: =IF($D11=2023,J11*'Average selling price'!$B$4, IF($D11=2024,J11*'Average selling price'!$C$4, IF($D11=2025,J11*'Average selling price'!$D$4,""))) -> 53840 | L11: 8280 | M11: 2475 | N11: =M11+L11 -> 10755 | O11: 1735 | P11: 0
A12: 44865 | B12: 1 | C12: =MONTH(A12) -> 10 | D12: 2023 | E12: CP11 | F12: 0 | G12: =IF(D12=2023,F12*'Average selling price'!$B$2, IF(D12=2024,F12*'Average selling price'!$C$2, IF(D12=2025,F12*'Average selling price'!$D$2,""))) -> 0 | H12: 0 | I12: =IF($D12=2023,H12*'Average selling price'!$B$3, IF($D12=2024,H12*'Average selling price'!$C$3, IF($D12=2025,H12*'Average selling price'!$D$3,""))) -> 0 | J12: 2 | K12: =IF($D12=2023,J12*'Average selling price'!$B$4, IF($D12=2024,J12*'Average selling price'!$C$4, IF($D12=2025,J12*'Average selling price'!$D$4,""))) -> 21536 | L12: 0 | M12: 8140 | N12: =M12+L12 -> 8140 | O12: 0 | P12: 0
A13: 44865 | B13: 1 | C13: =MONTH(A13) -> 10 | D13: 2023 | E13: CP12 | F13: 0 | G13: =IF(D13=2023,F13*'Average selling price'!$B$2, IF(D13=2024,F13*'Average selling price'!$C$2, IF(D13=2025,F13*'Average selling price'!$D$2,""))) -> 0 | H13: 1 | I13: =IF($D13=2023,H13*'Average selling price'!$B$3, IF($D13=2024,H13*'Average selling price'!$C$3, IF($D13=2025,H13*'Average selling price'!$D$3,""))) -> 29064 | J13: 1 | K13: =IF($D13=2023,J13*'Average selling price'!$B$4, IF($D13=2024,J13*'Average selling price'!$C$4, IF($D13=2025,J13*'Average selling price'!$D$4,""))) -> 10768 | L13: 2900 | M13: 0 | N13: =M13+L13 -> 2900 | O13: 0 | P13: 0
A14: 44865 | B14: 1 | C14: =MONTH(A14) -> 10 | D14: 2023 | E14: CP13 | F14: 1 | G14: =IF(D14=2023,F14*'Average selling price'!$B$2, IF(D14=2024,F14*'Average selling price'!$C$2, IF(D14=2025,F14*'Average selling price'!$D$2,""))) -> 4919 | H14: 3 | I14: =IF($D14=2023,H14*'Average selling price'!$B$3, IF($D14=2024,H14*'Average selling price'!$C$3, IF($D14=2025,H14*'Average selling price'!$D$3,""))) -> 87192 | J14: 1 | K14: =IF($D14=2023,J14*'Average selling price'!$B$4, IF($D14=2024,J14*'Average selling price'!$C$4, IF($D14=2025,J14*'Average selling price'!$D$4,""))) -> 10768 | L14: 1935 | M14: 0 | N14: =M14+L14 -> 1935 | O14: 0 | P14: 355
A15: 44865 | B15: 1 | C15: =MONTH(A15) -> 10 | D15: 2023 | E15: CP15 | F15: 0 | G15: =IF(D15=2023,F15*'Average selling price'!$B$2, IF(D15=2024,F15*'Average selling price'!$C$2, IF(D15=2025,F15*'Average selling price'!$D$2,""))) -> 0 | H15: 0 | I15: =IF($D15=2023,H15*'Average selling price'!$B$3, IF($D15=2024,H15*'Average selling price'!$C$3, IF($D15=2025,H15*'Average selling price'!$D$3,""))) -> 0 | J15: 0 | K15: =IF($D15=2023,J15*'Average selling price'!$B$4, IF($D15=2024,J15*'Average selling price'!$C$4, IF($D15=2025,J15*'Average selling price'!$D$4,""))) -> 0 | L15: 4905 | M15: 24630 | N15: =M15+L15 -> 29535 | O15: 3699 | P15: 25
... A26: 44865 | B26: 1 | C26: =MONTH(A26) -> 10 | D26: 2023 | E26: CP32 | F26: 1 | G26: =IF(D26=2023,F26*'Average selling price'!$B$2, IF(D26=2024,F26*'Average selling price'!$C$2, IF(D26=2025,F26*'Average selling price'!$D$2,""))) -> 4919 | H26: 0 | I26: =IF($D26=2023,H26*'Average selling price'!$B$3, IF($D26=2024,H26*'Average selling price'!$C$3, IF($D26=2025,H26*'Average selling price'!$D$3,""))) -> 0 | J26: 0 | K26: =IF($D26=2023,J26*'Average selling price'!$B$4, IF($D26=2024,J26*'Average selling price'!$C$4, IF($D26=2025,J26*'Average selling price'!$D$4,""))) -> 0 | L26: 4455 | M26: 2400 | N26: =M26+L26 -> 6855 | O26: 3635 | P26: 125
A27: 44865 | B27: 1 | C27: =MONTH(A27) -> 10 | D27: 2023 | E27: CP33 | F27: 0 | G27: =IF(D27=2023,F27*'Average selling price'!$B$2, IF(D27=2024,F27*'Average selling price'!$C$2, IF(D27=2025,F27*'Average selling price'!$D$2,""))) -> 0 | H27: 0 | I27: =IF($D27=2023,H27*'Average selling price'!$B$3, IF($D27=2024,H27*'Average selling price'!$C$3, IF($D27=2025,H27*'Average selling price'!$D$3,""))) -> 0 | J27: 1 | K27: =IF($D27=2023,J27*'Average selling price'!$B$4, IF($D27=2024,J27*'Average selling price'!$C$4, IF($D27=2025,J27*'Average selling price'!$D$4,""))) -> 10768 | L27: 0 | M27: 450 | N27: =M27+L27 -> 450 | P27: 0
A28: 44865 | B28: 1 | C28: =MONTH(A28) -> 10 | D28: 2023 | E28: CP35 | F28: 0 | G28: =IF(D28=2023,F28*'Average selling price'!$B$2, IF(D28=2024,F28*'Average selling price'!$C$2, IF(D28=2025,F28*'Average selling price'!$D$2,""))) -> 0 | H28: 0 | I28: =IF($D28=2023,H28*'Average selling price'!$B$3, IF($D28=2024,H28*'Average selling price'!$C$3, IF($D28=2025,H28*'Average selling price'!$D$3,""))) -> 0 | J28: 0 | K28: =IF($D28=2023,J28*'Average selling price'!$B$4, IF($D28=2024,J28*'Average selling price'!$C$4, IF($D28=2025,J28*'Average selling price'!$D$4,""))) -> 0 | L28: 0 | M28: 0 | N28: =M28+L28 -> 0 | O28: 0 | P28: 0
A29: 44865 | B29: 1 | C29: =MONTH(A29) -> 10 | D29: 2023 | E29: CP36 | F29: 0 | G29: =IF(D29=2023,F29*'Average selling price'!$B$2, IF(D29=2024,F29*'Average selling price'!$C$2, IF(D29=2025,F29*'Average selling price'!$D$2,""))) -> 0 | H29: 0 | I29: =IF($D29=2023,H29*'Average selling price'!$B$3, IF($D29=2024,H29*'Average selling price'!$C$3, IF($D29=2025,H29*'Average selling price'!$D$3,""))) -> 0 | J29: 1 | K29: =IF($D29=2023,J29*'Average selling price'!$B$4, IF($D29=2024,J29*'Average selling price'!$C$4, IF($D29=2025,J29*'Average selling price'!$D$4,""))) -> 10768 | L29: 5553 | M29: 4626 | N29: =M29+L29 -> 10179 | O29: 0 | P29: 0
A30: 44865 | B30: 1 | C30: =MONTH(A30) -> 10 | D30: 2023 | E30: CP37 | F30: 0 | G30: =IF(D30=2023,F30*'Average selling price'!$B$2, IF(D30=2024,F30*'Average selling price'!$C$2, IF(D30=2025,F30*'Average selling price'!$D$2,""))) -> 0 | H30: 0 | I30: =IF($D30=2023,H30*'Average selling price'!$B$3, IF($D30=2024,H30*'Average selling price'!$C$3, IF($D30=2025,H30*'Average selling price'!$D$3,""))) -> 0 | J30: 1 | K30: =IF($D30=2023,J30*'Average selling price'!$B$4, IF($D30=2024,J30*'Average selling price'!$C$4, IF($D30=2025,J30*'Average selling price'!$D$4,""))) -> 10768 | L30: 5007 | M30: 2100 | N30: =M30+L30 -> 7107 | O30: 710 | P30: 0
A31: 44865 | B31: 1 | C31: =MONTH(A31) -> 10 | D31: 2023 | E31: CP39 | F31: 0 | G31: =IF(D31=2023,F31*'Average selling price'!$B$2, IF(D31=2024,F31*'Average selling price'!$C$2, IF(D31=2025,F31*'Average selling price'!$D$2,""))) -> 0 | H31: 0 | I31: =IF($D31=2023,H31*'Average selling price'!$B$3, IF($D31=2024,H31*'Average selling price'!$C$3, IF($D31=2025,H31*'Average selling price'!$D$3,""))) -> 0 | J31: 0 | K31: =IF($D31=2023,J31*'Average selling price'!$B$4, IF($D31=2024,J31*'Average selling price'!$C$4, IF($D31=2025,J31*'Average selling price'!$D$4,""))) -> 0 | L31: 0 | M31: 0 | N31: =M31+L31 -> 0 | O31: 0 | P31: 0
A32: 44865 | B32: 1 | C32: =MONTH(A32) -> 10 | D32: 2023 | E32: CP40 | F32: 2 | G32: =IF(D32=2023,F32*'Average selling price'!$B$2, IF(D32=2024,F32*'Average selling price'!$C$2, IF(D32=2025,F32*'Average selling price'!$D$2,""))) -> 9838 | H32: 0 | I32: =IF($D32=2023,H32*'Average selling price'!$B$3, IF($D32=2024,H32*'Average selling price'!$C$3, IF($D32=2025,H32*'Average selling price'!$D$3,""))) -> 0 | J32: 0 | K32: =IF($D32=2023,J32*'Average selling price'!$B$4, IF($D32=2024,J32*'Average selling price'!$C$4, IF($D32=2025,J32*'Average selling price'!$D$4,""))) -> 0 | L32: 0 | M32: 0 | N32: =M32+L32 -> 0 | O32: 949 | P32: 0
A33: 44865 | B33: 1 | C33: =MONTH(A33) -> 10 | D33: 2023 | E33: CP41 | F33: 1 | G33: =IF(D33=2023,F33*'Average selling price'!$B$2, IF(D33=2024,F33*'Average selling price'!$C$2, IF(D33=2025,F33*'Average selling price'!$D$2,""))) -> 4919 | H33: 0 | I33: =IF($D33=2023,H33*'Average selling price'!$B$3, IF($D33=2024,H33*'Average selling price'!$C$3, IF($D33=2025,H33*'Average selling price'!$D$3,""))) -> 0 | J33: 1 | K33: =IF($D33=2023,J33*'Average selling price'!$B$4, IF($D33=2024,J33*'Average selling price'!$C$4, IF($D33=2025,J33*'Average selling price'!$D$4,""))) -> 10768 | L33: 3179 | M33: 4650 | N33: =M33+L33 -> 7829 | O33: 1300 | P33: 0
A34: 44865 | B34: 1 | C34: =MONTH(A34) -> 10 | D34: 2023 | E34: CP42 | F34: 0 | G34: =IF(D34=2023,F34*'Average selling price'!$B$2, IF(D34=2024,F34*'Average selling price'!$C$2, IF(D34=2025,F34*'Average selling price'!$D$2,""))) -> 0 | H34: 0 | I34: =IF($D34=2023,H34*'Average selling price'!$B$3, IF($D34=2024,H34*'Average selling price'!$C$3, IF($D34=2025,H34*'Average selling price'!$D$3,""))) -> 0 | J34: 0 | K34: =IF($D34=2023,J34*'Average selling price'!$B$4, IF($D34=2024,J34*'Average selling price'!$C$4, IF($D34=2025,J34*'Average selling price'!$D$4,""))) -> 0 | L34: 0 | M34: 0 | N34: =M34+L34 -> 0 | O34: 0 | P34: 0
A35: 44865 | B35: 1 | C35: =MONTH(A35) -> 10 | D35: 2023 | E35: CP43 | F35: 1 | G35: =IF(D35=2023,F35*'Average selling price'!$B$2, IF(D35=2024,F35*'Average selling price'!$C$2, IF(D35=2025,F35*'Average selling price'!$D$2,""))) -> 4919 | H35: 0 | I35: =IF($D35=2023,H35*'Average selling price'!$B$3, IF($D35=2024,H35*'Average selling price'!$C$3, IF($D35=2025,H35*'Average selling price'!$D$3,""))) -> 0 | J35: 0 | K35: =IF($D35=2023,J35*'Average selling price'!$B$4, IF($D35=2024,J35*'Average selling price'!$C$4, IF($D35=2025,J35*'Average selling price'!$D$4,""))) -> 0 | L35: 9040 | M35: 370 | N35: =M35+L35 -> 9410 | O35: 0 | P35: 0
A36: 44865 | B36: 1 | C36: =MONTH(A36) -> 10 | D36: 2023 | E36: CP44 | F36: 0 | G36: =IF(D36=2023,F36*'Average selling price'!$B$2, IF(D36=2024,F36*'Average selling price'!$C$2, IF(D36=2025,F36*'Average selling price'!$D$2,""))) -> 0 | H36: 0 | I36: =IF($D36=2023,H36*'Average selling price'!$B$3, IF($D36=2024,H36*'Average selling price'!$C$3, IF($D36=2025,H36*'Average selling price'!$D$3,""))) -> 0 | J36: 1 | K36: =IF($D36=2023,J36*'Average selling price'!$B$4, IF($D36=2024,J36*'Average selling price'!$C$4, IF($D36=2025,J36*'Average selling price'!$D$4,""))) -> 10768 | L36: 4975 | M36: 10600 | N36: =M36+L36 -> 15575 | O36: 0 | P36: 470
A37: 44865 | B37: 1 | C37: =MONTH(A37) -> 10 | D37: 2023 | E37: CP45 | F37: 0 | G37: =IF(D37=2023,F37*'Average selling price'!$B$2, IF(D37=2024,F37*'Average selling price'!$C$2, IF(D37=2025,F37*'Average selling price'!$D$2,""))) -> 0 | H37: 0 | I37: =IF($D37=2023,H37*'Average selling price'!$B$3, IF($D37=2024,H37*'Average selling price'!$C$3, IF($D37=2025,H37*'Average selling price'!$D$3,""))) -> 0 | J37: 0 | K37: =IF($D37=2023,J37*'Average selling price'!$B$4, IF($D37=2024,J37*'Average selling price'!$C$4, IF($D37=2025,J37*'Average selling price'!$D$4,""))) -> 0 | L37: 1494 | M37: 0 | N37: =M37+L37 -> 1494 | O37: 0 | P37: 73
A38: 44865 | B38: 1 | C38: =MONTH(A38) -> 10 | D38: 2023 | E38: CP46 | F38: 0 | G38: =IF(D38=2023,F38*'Average selling price'!$B$2, IF(D38=2024,F38*'Average selling price'!$C$2, IF(D38=2025,F38*'Average selling price'!$D$2,""))) -> 0 | H38: 0 | I38: =IF($D38=2023,H38*'Average selling price'!$B$3, IF($D38=2024,H38*'Average selling price'!$C$3, IF($D38=2025,H38*'Average selling price'!$D$3,""))) -> 0 | J38: 0 | K38: =IF($D38=2023,J38*'Average selling price'!$B$4, IF($D38=2024,J38*'Average selling price'!$C$4, IF($D38=2025,J38*'Average selling price'!$D$4,""))) -> 0 | L38: 542 | M38: 1818 | N38: =M38+L38 -> 2360 | O38: 78 | P38: 116
A39: 44865 | B39: 1 | C39: =MONTH(A39) -> 10 | D39: 2023 | E39: CP47 | F39: -1 | G39: =IF(D39=2023,F39*'Average selling price'!$B$2, IF(D39=2024,F39*'Average selling price'!$C$2, IF(D39=2025,F39*'Average selling price'!$D$2,""))) -> -4919 | H39: 0 | I39: =IF($D39=2023,H39*'Average selling price'!$B$3, IF($D39=2024,H39*'Average selling price'!$C$3, IF($D39=2025,H39*'Average selling price'!$D$3,""))) -> 0 | J39: 0 | K39: =IF($D39=2023,J39*'Average selling price'!$B$4, IF($D39=2024,J39*'Average selling price'!$C$4, IF($D39=2025,J39*'Average selling price'!$D$4,""))) -> 0 | L39: 23 | M39: 870 | N39: =M39+L39 -> 893 | O39: 2170 | P39: 214
... A2100: 45229 | B2100: 53 | C2100: =MONTH(A2100) -> 10 | D2100: 2023 | E2100: CP11 | F2100: 0 | G2100: =IF(D2100=2023,F2100*'Average selling price'!$B$2, IF(D2100=2024,F2100*'Average selling price'!$C$2, IF(D2100=2025,F2100*'Average selling price'!$D$2,""))) -> 0 | H2100: 0 | I2100: =IF($D2100=2023,H2100*'Average selling price'!$B$3, IF($D2100=2024,H2100*'Average selling price'!$C$3, IF($D2100=2025,H2100*'Average selling price'!$D$3,""))) -> 0 | J2100: 0 | K2100: =IF($D2100=2023,J2100*'Average selling price'!$B$4, IF($D2100=2024,J2100*'Average selling price'!$C$4, IF($D2100=2025,J2100*'Average selling price'!$D$4,""))) -> 0 | L2100: 3011 | M2100: 2355 | N2100: =M2100+L2100 -> 5366 | O2100: 3120 | P2100: 108
A2101: 45229 | B2101: 53 | C2101: =MONTH(A2101) -> 10 | D2101: 2023 | E2101: CP12 | F2101: 2 | G2101: =IF(D2101=2023,F2101*'Average selling price'!$B$2, IF(D2101=2024,F2101*'Average selling price'!$C$2, IF(D2101=2025,F2101*'Average selling price'!$D$2,""))) -> 9838 | H2101: 0 | I2101: =IF($D2101=2023,H2101*'Average selling price'!$B$3, IF($D2101=2024,H2101*'Average selling price'!$C$3, IF($D2101=2025,H2101*'Average selling price'!$D$3,""))) -> 0 | K2101: =IF($D2101=2023,J2101*'Average selling price'!$B$4, IF($D2101=2024,J2101*'Average selling price'!$C$4, IF($D2101=2025,J2101*'Average selling price'!$D$4,""))) -> 0 | L2101: 2600 | M2101: 3350 | N2101: =M2101+L2101 -> 5950 | O2101: 9260 | P2101: 0
A2102: 45229 | B2102: 53 | C2102: =MONTH(A2102) -> 10 | D2102: 2023 | E2102: CP13 | F2102: 1 | G2102: =IF(D2102=2023,F2102*'Average selling price'!$B$2, IF(D2102=2024,F2102*'Average selling price'!$C$2, IF(D2102=2025,F2102*'Average selling price'!$D$2,""))) -> 4919 | H2102: 0 | I2102: =IF($D2102=2023,H2102*'Average selling price'!$B$3, IF($D2102=2024,H2102*'Average selling price'!$C$3, IF($D2102=2025,H2102*'Average selling price'!$D$3,""))) -> 0 | J2102: 3 | K2102: =IF($D2102=2023,J2102*'Average selling price'!$B$4, IF($D2102=2024,J2102*'Average selling price'!$C$4, IF($D2102=2025,J2102*'Average selling price'!$D$4,""))) -> 32304 | L2102: 6862 | M2102: 1700 | N2102: =M2102+L2102 -> 8562 | O2102: 125 | P2102: 0
A2103: 45229 | B2103: 53 | C2103: =MONTH(A2103) -> 10 | D2103: 2023 | E2103: CP15 | F2103: 3 | G2103: =IF(D2103=2023,F2103*'Average selling price'!$B$2, IF(D2103=2024,F2103*'Average selling price'!$C$2, IF(D2103=2025,F2103*'Average selling price'!$D$2,""))) -> 14757 | H2103: 0 | I2103: =IF($D2103=2023,H2103*'Average selling price'!$B$3, IF($D2103=2024,H2103*'Average selling price'!$C$3, IF($D2103=2025,H2103*'Average selling price'!$D$3,""))) -> 0 | J2103: 0 | K2103: =IF($D2103=2023,J2103*'Average selling price'!$B$4, IF($D2103=2024,J2103*'Average selling price'!$C$4, IF($D2103=2025,J2103*'Average selling price'!$D$4,""))) -> 0 | L2103: 1770 | M2103: 3260 | N2103: =M2103+L2103 -> 5030 | O2103: 1250 | P2103: 0
A2104: 45229 | B2104: 53 | C2104: =MONTH(A2104) -> 10 | D2104: 2023 | E2104: CP16 | F2104: 1 | G2104: =IF(D2104=2023,F2104*'Average selling price'!$B$2, IF(D2104=2024,F2104*'Average selling price'!$C$2, IF(D2104=2025,F2104*'Average selling price'!$D$2,""))) -> 4919 | H2104: 0 | I2104: =IF($D2104=2023,H2104*'Average selling price'!$B$3, IF($D2104=2024,H2104*'Average selling price'!$C$3, IF($D2104=2025,H2104*'Average selling price'!$D$3,""))) -> 0 | J2104: 0 | K2104: =IF($D2104=2023,J2104*'Average selling price'!$B$4, IF($D2104=2024,J2104*'Average selling price'!$C$4, IF($D2104=2025,J2104*'Average selling price'!$D$4,""))) -> 0 | L2104: 3565 | M2104: 3780 | N2104: =M2104+L2104 -> 7345 | O2104: 1900 | P2104: 0
A2105: 45229 | B2105: 53 | C2105: =MONTH(A2105) -> 10 | D2105: 2023 | E2105: CP17 | F2105: 1 | G2105: =IF(D2105=2023,F2105*'Average selling price'!$B$2, IF(D2105=2024,F2105*'Average selling price'!$C$2, IF(D2105=2025,F2105*'Average selling price'!$D$2,""))) -> 4919 | H2105: 0 | I2105: =IF($D2105=2023,H2105*'Average selling price'!$B$3, IF($D2105=2024,H2105*'Average selling price'!$C$3, IF($D2105=2025,H2105*'Average selling price'!$D$3,""))) -> 0 | J2105: 3 | K2105: =IF($D2105=2023,J2105*'Average selling price'!$B$4, IF($D2105=2024,J2105*'Average selling price'!$C$4, IF($D2105=2025,J2105*'Average selling price'!$D$4,""))) -> 32304 | L2105: 855 | M2105: 0 | N2105: =M2105+L2105 -> 855 | O2105: 1548 | P2105: -97
A2106: 45229 | B2106: 53 | C2106: =MONTH(A2106) -> 10 | D2106: 2023 | E2106: CP18 | F2106: 0 | G2106: =IF(D2106=2023,F2106*'Average selling price'!$B$2, IF(D2106=2024,F2106*'Average selling price'!$C$2, IF(D2106=2025,F2106*'Average selling price'!$D$2,""))) -> 0 | H2106: 0 | I2106: =IF($D2106=2023,H2106*'Average selling price'!$B$3, IF($D2106=2024,H2106*'Average selling price'!$C$3, IF($D2106=2025,H2106*'Average selling price'!$D$3,""))) -> 0 | J2106: 0 | K2106: =IF($D2106=2023,J2106*'Average selling price'!$B$4, IF($D2106=2024,J2106*'Average selling price'!$C$4, IF($D2106=2025,J2106*'Average selling price'!$D$4,""))) -> 0 | L2106: 2660 | M2106: 350 | N2106: =M2106+L2106 -> 3010 | O2106: 0 | P2106: 1301
A2107: 45229 | B2107: 53 | C2107: =MONTH(A2107) -> 10 | D2107: 2023 | E2107: CP20 | F2107: 0 | G2107: =IF(D2107=2023,F2107*'Average selling price'!$B$2, IF(D2107=2024,F2107*'Average selling price'!$C$2, IF(D2107=2025,F2107*'Average selling price'!$D$2,""))) -> 0 | H2107: 0 | I2107: =IF($D2107=2023,H2107*'Average selling price'!$B$3, IF($D2107=2024,H2107*'Average selling price'!$C$3, IF($D2107=2025,H2107*'Average selling price'!$D$3,""))) -> 0 | J2107: 0 | K2107: =IF($D2107=2023,J2107*'Average selling price'!$B$4, IF($D2107=2024,J2107*'Average selling price'!$C$4, IF($D2107=2025,J2107*'Average selling price'!$D$4,""))) -> 0 | L2107: 2977 | M2107: 12460 | N2107: =M2107+L2107 -> 15437 | O2107: 220 | P2107: 6
A2108: 45229 | B2108: 53 | C2108: =MONTH(A2108) -> 10 | D2108: 2023 | E2108: CP21 | F2108: 0 | G2108: =IF(D2108=2023,F2108*'Average selling price'!$B$2, IF(D2108=2024,F2108*'Average selling price'!$C$2, IF(D2108=2025,F2108*'Average selling price'!$D$2,""))) -> 0 | H2108: 0 | I2108: =IF($D2108=2023,H2108*'Average selling price'!$B$3, IF($D2108=2024,H2108*'Average selling price'!$C$3, IF($D2108=2025,H2108*'Average selling price'!$D$3,""))) -> 0 | J2108: 1 | K2108: =IF($D2108=2023,J2108*'Average selling price'!$B$4, IF($D2108=2024,J2108*'Average selling price'!$C$4, IF($D2108=2025,J2108*'Average selling price'!$D$4,""))) -> 10768 | L2108: 660 | M2108: 300 | N2108: =M2108+L2108 -> 960 | O2108: 3954 | P2108: 480
A2109: 45229 | B2109: 53 | C2109: =MONTH(A2109) -> 10 | D2109: 2023 | E2109: CP23 | F2109: 2 | G2109: =IF(D2109=2023,F2109*'Average selling price'!$B$2, IF(D2109=2024,F2109*'Average selling price'!$C$2, IF(D2109=2025,F2109*'Average selling price'!$D$2,""))) -> 9838 | H2109: 0 | I2109: =IF($D2109=2023,H2109*'Average selling price'!$B$3, IF($D2109=2024,H2109*'Average selling price'!$C$3, IF($D2109=2025,H2109*'Average selling price'!$D$3,""))) -> 0 | J2109: 1 | K2109: =IF($D2109=2023,J2109*'Average selling price'!$B$4, IF($D2109=2024,J2109*'Average selling price'!$C$4, IF($D2109=2025,J2109*'Average selling price'!$D$4,""))) -> 10768 | L2109: 10485 | M2109: 3850 | N2109: =M2109+L2109 -> 14335 | O2109: 3269 | P2109: 607
A2110: 45229 | B2110: 53 | C2110: =MONTH(A2110) -> 10 | D2110: 2023 | E2110: CP24 | F2110: 0 | G2110: =IF(D2110=2023,F2110*'Average selling price'!$B$2, IF(D2110=2024,F2110*'Average selling price'!$C$2, IF(D2110=2025,F2110*'Average selling price'!$D$2,""))) -> 0 | H2110: 0 | I2110: =IF($D2110=2023,H2110*'Average selling price'!$B$3, IF($D2110=2024,H2110*'Average selling price'!$C$3, IF($D2110=2025,H2110*'Average selling price'!$D$3,""))) -> 0 | J2110: 0 | K2110: =IF($D2110=2023,J2110*'Average selling price'!$B$4, IF($D2110=2024,J2110*'Average selling price'!$C$4, IF($D2110=2025,J2110*'Average selling price'!$D$4,""))) -> 0 | L2110: 0 | M2110: 0 | N2110: =M2110+L2110 -> 0 | O2110: 0 | P2110: 0
...

Sheet Average selling price
B1: 2023 | C1: 2024 | D1: 2025
A2: HT-Hors-terre | B2: 4919 | C2: 5286 | D2: 5750
A3: CR-Creusée | B3: 29064 | C3: 32755 | D3: 34677
A4: SP-Spa | B4: 10768 | C4: 11135 | D4: 11726
